<robot name="robot_arm">
 	<link name="base_link">
		<visual>
		    <origin xyz="0 0 0.03725" rpy="0 0 0"/>
			<geometry>
				<cylinder length="0.0755" radius="0.065"/>
			</geometry>
		</visual>	
	</link>

    <link name="base_rot">
		<visual>
          	<geometry>
                <box size="0.052 0.042 0.0553" />
			</geometry>
		</visual>	
	</link>
    
    <joint name="joint_0" type="revolute">
      <parent link="base_link"/>
      <child link="base_rot"/>
      <origin xyz="0 0 0.10315" rpy="0 0 0" />
      <axis xyz="0 0 -1"/>
      <limit lower="-2.356" upper="2.356" />
    </joint>
    
    <link name="arm1">
		<visual>
          <origin xyz="0 0 0.135" rpy="0 0 0" />
          	<geometry>
            	<cylinder length="0.270" radius="0.026"/>
			</geometry>
		</visual>	
	</link>
    <joint name="joint_1" type="revolute">
      <parent link="base_rot"/>
      <child link="arm1"/>
      <origin xyz="0 0 0.02765" rpy="0 0 0" />
      <axis xyz="-1 0 0"/>
      <limit lower="-1.57" upper="1.57" />
    </joint>
        <link name="base_arm2">
		<visual>
          	<geometry>
                <box size="0.052 0.042 0.026" />
			</geometry>
		</visual>	
	</link>
    <joint name="joint_2" type="revolute">
      <parent link="arm1"/>
      <child link="base_arm2"/>
      <origin xyz="0 0 0.27" rpy="0 0 0" />
      <axis xyz="-1 0 0"/>
      <limit lower="-1.57" upper="1.57" />
    </joint>
    <link name="arm2">
		<visual>
          <origin xyz="0 0.1 0" rpy="1.57 0 0" />
          	<geometry>
            	<cylinder length="0.2" radius="0.01"/>
			</geometry>
		</visual>	
	</link>
    <joint name="joint_3" type="revolute">
      <parent link="base_arm2"/>
      <child link="arm2"/>
      <origin xyz="0 0 0.043" rpy="0 0 0" />
      <axis xyz="0 1 0"/>
    <limit lower="-2.356" upper="2.356" />
    </joint>
    
    <link name="tilt">
		<visual>
          <origin xyz="0 0.03825 0" rpy="1.57 0 0" />
          	<geometry>
            	<box size="0.025 0.025 0.0765" />
			</geometry>
		</visual>	
    </link>

    <joint name="joint_4" type="revolute">
      <parent link="arm2"/>
      <child link="tilt"/>
      <origin xyz="0 0.2 0" rpy="0 0 0" />
      <axis xyz="-1 0 0"/>
      <limit lower="-1.57" upper="1.57" />       
    </joint>
    
    <link name="top">
		<visual>
          <origin xyz="0 0.065 0" rpy="1.57 0 0" />
          	<geometry>
            	<box size="0.025 0.025 0.130" />
			</geometry>
		</visual>	
	</link>
    
    <joint name="joint_5" type="revolute">
      <parent link="tilt"/>
      <child link="top"/>
      <origin xyz="0 0.0767 0" rpy="0 0 0" />
      <axis xyz="0 -1 0"/>
      <limit lower="-2.356" upper="2.356" />       
    </joint>

  <link name="End">
		<visual>
          <origin xyz="0 0 0" rpy="0 0 0" />
          	<geometry>
            	<box size="0 0 0" />
			</geometry>
		</visual>	
	</link>

    <joint name="joint_end" type="revolute">
      <parent link="top"/>
      <child link="End"/>
      <origin xyz="0 0.13 0" rpy="0 0 0" />
      <axis xyz="0 1 0"/>      
    </joint>
</robot>